{
    "id": "12f59a58-4e48-4359-b07e-1e70817e1f74",
    "title": "Sign up",
    "signature": "test_base.py::TestClass::test_sign_up",
    "run_id": null,
    "testops_id": 2,
    "execution": {
        "start_time": 1691058127.226882,
        "status": "failed",
        "end_time": 1691058127.2469351,
        "duration": 20,
        "stacktrace": "self = <tests.test_base.TestClass object at 0x105bd93f0>\n\n    @qase.id(2)\n    @qase.title(\"Sign up\")\n    @qase.fields(\n        (\"severity\", \"critical\"),\n        (\"priority\", \"hight\"),\n        (\"layer\", \"e2e\"),\n        (\"description\", \"Sign up user\"),\n        (\"description\", \"*Precondition 1*. Markdown is supported.\"),\n    )\n    def test_sign_up(self):\n>       assert 1 != 1, \"Assertion failed to to unexpected value\"\nE       AssertionError: Assertion failed to to unexpected value\nE       assert 1 != 1\n\ntest_base.py:28: AssertionError",
        "thread": "79884-MainThread"
    },
    "fields": {
        "severity": "critical",
        "priority": "hight",
        "layer": "e2e",
        "description": "*Precondition 1*. Markdown is supported."
    },
    "attachments": [],
    "steps": [],
    "params": {},
    "author": null,
    "relations": [],
    "muted": false,
    "message": "AssertionError: Assertion failed to to unexpected value\nassert 1 != 1"
}